Workbook

Sheet summary_data_Futures
A1: JPXデリバティブ取引市況(概要_先物取引)
A2: JPX Derivatives Market Report
A3: =DATE(2026,07,17) -> 46220
A4: =DATE(2026,07,17) -> 46220
A6: （注）「総取引高」は立会取引及びJ-NET(商品先物(TOCOM)は立会外。以下同じ。)の合計、「うち立会外」はJ-NET分を内数表示。取引高、取引金額はストラテジー取引を含む。
A7: NOTE: Total : Total of Auction and J-NET Market (Off-floor Trading for TOCOM Commodity Futures)
A8: J-NET : J-NET Market (Off-floor Trading for TOCOM Commodity Futures) indicated in parentheses
A9: Trading Volume and Value includes Strategy Trades.
B10: 商品名 | C10: 場区分 | D10: 取引高 （単位） Trading Volume (unit) | F10: 全体に占める比率 Market share of Total Volume | G10: 取引金額 （円） Trading Value (￥) | I10: 全体に占める比率 Market share of Total Value
B11: Products | C11: Session | D11: 総取引高 Total | E11: うち立会外 J-NET | G11: 総取引金額 Total | H11: うち立会外 J-NET
A12: JPX | B12: JPX先物合計 JPX Futures Total | C12: 夜間 Night | D12: =857955.0 -> 857955 | E12: =46229.0 -> 46229 | F12: =1.0 -> 1 | G12: =5501890718077.0 -> 5501890718077 | H12: =440382391352.0 -> 440382391352 | I12: =1.0 -> 1
C13: 前場 Morning | D13: =652869.0 -> 652869 | E13: =30451.0 -> 30451 | F13: =1.0 -> 1 | G13: =6111389994980.0 -> 6111389994980 | H13: =632377820855.0 -> 632377820855 | I13: =1.0 -> 1
C14: 後場 Afternoon | D14: =880405.0 -> 880405 | E14: =51838.0 -> 51838 | F14: =1.0 -> 1 | G14: =9122497727725.0 -> 9122497727725 | H14: =1123264100750.0 -> 1123264100750 | I14: =1.0 -> 1
C15: 合計 Total | D15: =2391229.0 -> 2391229 | E15: =128518.0 -> 128518 | F15: =1.0 -> 1 | G15: =20735778440782.0 -> 20735778440782 | H15: =2196024312957.0 -> 2196024312957 | I15: =1.0 -> 1
A16: OSE | B16: 国債先物・金利先物 JGB・Interest Rate Futures | C16: 夜間 Night | D16: =15819.0 -> 15819 | E16: =99.0 -> 99 | F16: =0.018 -> 0.018 | G16: =1273654044375.0 -> 1273654044375 | H16: =12635680000.0 -> 12635680000 | I16: =0.231 -> 0.231
C17: 前場 Morning | D17: =14962.0 -> 14962 | E17: =2894.0 -> 2894 | F17: =0.023 -> 0.023 | G17: =1847461401875.0 -> 1847461401875 | H17: =369410330000.0 -> 369410330000 | I17: =0.302 -> 0.302
C18: 後場 Afternoon | D18: =21538.0 -> 21538 | E18: =1090.0 -> 1090 | F18: =0.024 -> 0.024 | G18: =2318130743125.0 -> 2318130743125 | H18: =139266435000.0 -> 139266435000 | I18: =0.254 -> 0.254
C19: 合計 Total | D19: =52319.0 -> 52319 | E19: =4083.0 -> 4083 | F19: =0.022 -> 0.022 | G19: =5439246189375.0 -> 5439246189375 | H19: =521312445000.0 -> 521312445000 | I19: =0.262 -> 0.262
B20: 指数先物 Index Futures | C20: 夜間 Night | D20: =826062.0 -> 826062 | E20: =46130.0 -> 46130 | F20: =0.963 -> 0.963 | G20: =4080635024102.0 -> 4080635024102 | H20: =427746711352.0 -> 427746711352 | I20: =0.742 -> 0.742
C21: 前場 Morning | D21: =632910.0 -> 632910 | E21: =27547.0 -> 27547 | F21: =0.969 -> 0.969 | G21: =4211802335605.0 -> 4211802335605 | H21: =262953726855.0 -> 262953726855 | I21: =0.689 -> 0.689
C22: 後場 Afternoon | D22: =848215.0 -> 848215 | E22: =50436.0 -> 50436 | F22: =0.963 -> 0.963 | G22: =6716235959100.0 -> 6716235959100 | H22: =983568936150.0 -> 983568936150 | I22: =0.736 -> 0.736
C23: 合計 Total | D23: =2307187.0 -> 2307187 | E23: =124113.0 -> 124113 | F23: =0.965 -> 0.965 | G23: =15008673318807.0 -> 15008673318807 | H23: =1674269374357.0 -> 1674269374357 | I23: =0.724 -> 0.724
B24: 商品先物(OSE) OSE Commodity Futures | C24: 夜間 Night | D24: =15572.0 -> 15572 | E24: =0.0 -> 0 | F24: =0.018 -> 0.018 | G24: =145655508100.0 -> 145655508100 | H24: =0.0 -> 0 | I24: =0.026 -> 0.026
C25: 前場 Morning | D25: =4817.0 -> 4817 | E25: =0.0 -> 0 | F25: =0.007 -> 0.007 | G25: =51452375500.0 -> 51452375500 | H25: =0.0 -> 0 | I25: =0.008 -> 0.008
C26: 後場 Afternoon | D26: =9545.0 -> 9545 | E26: =0.0 -> 0 | F26: =0.011 -> 0.011 | G26: =84631166400.0 -> 84631166400 | H26: =0.0 -> 0 | I26: =0.009 -> 0.009
C27: 合計 Total | D27: =29934.0 -> 29934 | E27: =0.0 -> 0 | F27: =0.013 -> 0.013 | G27: =281739050000.0 -> 281739050000 | H27: =0.0 -> 0 | I27: =0.014 -> 0.014
A28: TOCOM | B28: 商品先物(TOCOM) TOCOM Commodity Futures | C28: 夜間 Night | D28: =502.0 -> 502 | E28: =0.0 -> 0 | F28: =0.001 -> 0.001 | G28: =1946141500.0 -> 1946141500 | H28: =0.0 -> 0 | I28: =0.0 -> 0
C29: 前場 Morning | D29: =180.0 -> 180 | E29: =10.0 -> 10 | F29: =0.0 -> 0 | G29: =673882000.0 -> 673882000 | H29: =13764000.0 -> 13764000 | I29: =0.0 -> 0
C30: 後場 Afternoon | D30: =1107.0 -> 1107 | E30: =312.0 -> 312 | F30: =0.001 -> 0.001 | G30: =3499859100.0 -> 3499859100 | H30: =428729600.0 -> 428729600 | I30: =0.0 -> 0
C31: 合計 Total | D31: =1789.0 -> 1789 | E31: =322.0 -> 322 | F31: =0.001 -> 0.001 | G31: =6119882600.0 -> 6119882600 | H31: =442493600.0 -> 442493600 | I31: =0.0 -> 0

Sheet summary_data_OP
A1: JPXデリバティブ取引市況(概要_オプション取引)
A2: JPX Derivatives Market Report
A3: =summary_data_Futures!A3:I3 -> 46220
A4: =summary_data_Futures!A4:I4 -> 46220
A6: （注）「総取引高」は立会取引及びJ-NETの合計、「うち立会外」はJ-NET分を内数表示。
A7: NOTE: Total : Total of Auction and J-NET Market.
A8: J-NET : J-NET Market indicated in parentheses
B9: 商品名 | C9: 場区分 | D9: 取引高 （単位） Trading Volume (unit) | F9: 全体に占める比率 Market share of Total Volume | G9: 取引金額 （円） Trading Value (￥) | I9: 全体に占める比率 Market share of Total Value
B10: Products | C10: Session | D10: 総取引高 Total | E10: うち立会外 J-NET | G10: 総取引金額 Total | H10: うち立会外 J-NET
A11: JPX | B11: JPXオプション合計 JPX Options Total | C11: 夜間 Night | D11: =20412 -> 20412 | E11: =4985 -> 4985 | F11: =1 -> 1 | G11: =7940632790 -> 7940632790 | H11: =6259846190 -> 6259846190 | I11: =1 -> 1
C12: 前場 Morning | D12: =69868 -> 69868 | E12: =8419 -> 8419 | F12: =1 -> 1 | G12: =15175499333 -> 15175499333 | H12: =10409744400 -> 10409744400 | I12: =1 -> 1
C13: 後場 Afternoon | D13: =75287 -> 75287 | E13: =26178 -> 26178 | F13: =1 -> 1 | G13: =51964244490 -> 51964244490 | H13: =42534821148 -> 42534821148 | I13: =1 -> 1
C14: 合計 Total | D14: =165567 -> 165567 | E14: =39582 -> 39582 | F14: =1 -> 1 | G14: =75080376613 -> 75080376613 | H14: =59204411738 -> 59204411738 | I14: =1 -> 1
A15: OSE | B15: 国債先物オプション Options on 10-year JGB Futures | C15: 夜間 Night | D15: =0 -> 0 | E15: =0 -> 0 | F15: =0 -> 0 | G15: =0 -> 0 | H15: =0 -> 0 | I15: =0 -> 0
C16: 前場 Morning | D16: =51 -> 51 | E16: =0 -> 0 | F16: =0.001 -> 0.001 | G16: =9900000 -> 9900000 | H16: =0 -> 0 | I16: =0.001 -> 0.001
C17: 後場 Afternoon | D17: =441 -> 441 | E17: =60 -> 60 | F17: =0.006 -> 0.006 | G17: =40890000 -> 40890000 | H17: =6900000 -> 6900000 | I17: =0.001 -> 0.001
C18: 合計 Total | D18: =492 -> 492 | E18: =60 -> 60 | F18: =0.003 -> 0.003 | G18: =50790000 -> 50790000 | H18: =6900000 -> 6900000 | I18: =0.001 -> 0.001
B19: 指数オプション Index Options | C19: 夜間 Night | D19: =20412 -> 20412 | E19: =4985 -> 4985 | F19: =1 -> 1 | G19: =7940632790 -> 7940632790 | H19: =6259846190 -> 6259846190 | I19: =1 -> 1
C20: 前場 Morning | D20: =33117 -> 33117 | E20: =8419 -> 8419 | F20: =0.474 -> 0.474 | G20: =15093795100 -> 15093795100 | H20: =10409744400 -> 10409744400 | I20: =0.995 -> 0.995
C21: 後場 Afternoon | D21: =61297 -> 61297 | E21: =23618 -> 23618 | F21: =0.814 -> 0.814 | G21: =51610983148 -> 51610983148 | H21: =42388171148 -> 42388171148 | I21: =0.993 -> 0.993
C22: 合計 Total | D22: =114826 -> 114826 | E22: =37022 -> 37022 | F22: =0.694 -> 0.694 | G22: =74645411038 -> 74645411038 | H22: =59057761738 -> 59057761738 | I22: =0.994 -> 0.994
B23: 有価証券オプション Securities Options | C23: 夜間 Night | D23: ="－" -> － | E23: ="－" -> － | F23: ="－" -> － | G23: ="－" -> － | H23: ="－" -> － | I23: ="－" -> －
C24: 前場 Morning | D24: =36700 -> 36700 | E24: =0 -> 0 | F24: =0.525 -> 0.525 | G24: =71804233 -> 71804233 | H24: =0 -> 0 | I24: =0.005 -> 0.005
C25: 後場 Afternoon | D25: =13549 -> 13549 | E25: =2500 -> 2500 | F25: =0.18 -> 0.18 | G25: =312371342 -> 312371342 | H25: =139750000 -> 139750000 | I25: =0.006 -> 0.006
C26: 合計 Total | D26: =50249 -> 50249 | E26: =2500 -> 2500 | F26: =0.303 -> 0.303 | G26: =384175575 -> 384175575 | H26: =139750000 -> 139750000 | I26: =0.005 -> 0.005
B27: 商品先物オプション(OSE) OSE Commodity Options | C27: 夜間 Night | D27: =0 -> 0 | E27: =0 -> 0 | F27: =0 -> 0 | G27: =0 -> 0 | H27: =0 -> 0 | I27: =0 -> 0
C28: 前場 Morning | D28: =0 -> 0 | E28: =0 -> 0 | F28: =0 -> 0 | G28: =0 -> 0 | H28: =0 -> 0 | I28: =0 -> 0
C29: 後場 Afternoon | D29: =0 -> 0 | E29: =0 -> 0 | F29: =0 -> 0 | G29: =0 -> 0 | H29: =0 -> 0 | I29: =0 -> 0
C30: 合計 Total | D30: =0 -> 0 | E30: =0 -> 0 | F30: =0 -> 0 | G30: =0 -> 0 | H30: =0 -> 0 | I30: =0 -> 0

Sheet market_data_Futures
A1: JPXデリバティブ取引市況(先物取引)
A2: JPX Derivatives Market Report
A3: =summary_data_Futures!A3:I3 -> 46220
A4: =summary_data_Futures!A4:I4 -> 46220
A6: （注）「総取引高」は立会取引及びJ-NET(商品先物(TOCOM)は立会外。以下同じ。)の合計、「うち立会外」はJ-NET分を内数表示。取引高、取引代金はストラテジー取引を含む。
A7: NOTE: Total : Total of Auction and J-NET Market (Off-floor Trading for TOCOM Commodity Futures)
A8: J-NET : J-NET Market (Off-floor Trading for TOCOM Commodity Futures) indicated in parentheses
A9: Trading Volume and Value includes Strategy Trades.
C10: 商品名 | D10: 場区分 | E10: 取引高 （単位） Trading Volume (unit) | G10: 取引金額 （円） Trading Value (￥)
C11: Products | D11: Session | E11: 総取引高 Total | F11: うち立会外 J-NET | G11: 総取引金額 Total | H11: うち立会外 J-NET
A12: OSE | B12: 指数先物 Index Futures | C12: 日経225先物 Nikkei 225 Futures | D12: 夜間 Night | E12: 16786 | F12: =2009 -> 2009 | G12: 1113693914152 | H12: =133325977152 -> 133325977152
D13: 前場 Morning | E13: 19631 | F13: =1418 -> 1418 | G13: 1274566914645 | H13: =92215257645 -> 92215257645
D14: 後場 Afternoon | E14: 41519 | F14: =10426 -> 10426 | G14: 2651366745060 | H14: =668213617060 -> 668213617060
D15: 合計 Total | E15: 77936 | F15: =13853 -> 13853 | G15: 5039627573857 | H15: =893754851857 -> 893754851857
C16: 日経225mini Nikkei 225 mini | D16: 夜間 Night | E16: 305881 | F16: =43541 -> 43541 | G16: 2029642274010 | H16: =289028512010 -> 289028512010
D17: 前場 Morning | E17: 262701 | F17: =25560 -> 25560 | G17: 1704443569410 | H17: =165857032510 -> 165857032510
D18: 後場 Afternoon | E18: 347876 | F18: =36800 -> 36800 | G18: 2217057427940 | H18: =234448425940 -> 234448425940
D19: 合計 Total | E19: 916458 | F19: =105901 -> 105901 | G19: 5951143271360 | H19: =689333970460 -> 689333970460
C20: 日経225マイクロ先物 Nikkei 225 Micro Futures | D20: 夜間 Night | E20: 482414 | F20: ="－" -> － | G20: 320144038500 | H20: ="－" -> －
D21: 前場 Morning | E21: 311222 | F21: ="－" -> － | G21: 201920621850 | H21: ="－" -> －
D22: 後場 Afternoon | E22: 401179 | F22: ="－" -> － | G22: 255593115750 | H22: ="－" -> －
D23: 合計 Total | E23: 1194815 | F23: ="－" -> － | G23: 777657776100 | H23: ="－" -> －
C24: TOPIX TOPIX Futures | D24: 夜間 Night | E24: 14781 | F24: =86 -> 86 | G24: 593851309200 | H24: =3465519200 -> 3465519200
D25: 前場 Morning | E25: 24594 | F25: =79 -> 79 | G25: 976671366500 | H25: =3147571500 -> 3147571500
D26: 後場 Afternoon | E26: 39061 | F26: =1979 -> 1979 | G26: 1527277130200 | H26: =77421570200 -> 77421570200
D27: 合計 Total | E27: 78436 | F27: =2144 -> 2144 | G27: 3097799805900 | H27: =84034660900 -> 84034660900
C28: ミニTOPIX mini-TOPIX Futures | D28: 夜間 Night | E28: 4856 | F28: =472 -> 472 | G28: 19508231650 | H28: =1896228400 -> 1896228400
D29: 前場 Morning | E29: 12234 | F29: =425 -> 425 | G29: 48570064400 | H29: =1688803400 -> 1688803400
D30: 後場 Afternoon | E30: 14074 | F30: =501 -> 501 | G30: 54997901050 | H30: =1957578550 -> 1957578550
D31: 合計 Total | E31: 31164 | F31: =1398 -> 1398 | G31: 123076197100 | H31: =5542610350 -> 5542610350
C32: JPXプライム150指数先物 JPX Prime 150 Index Futures | D32: 夜間 Night | E32: 0 | F32: =0 -> 0 | G32: 0 | H32: =0 -> 0
D33: 前場 Morning | E33: 0 | F33: =0 -> 0 | G33: 0 | H33: =0 -> 0
D34: 後場 Afternoon | E34: 0 | F34: =0 -> 0 | G34: 0 | H34: =0 -> 0
D35: 合計 Total | E35: 0 | F35: =0 -> 0 | G35: 0 | H35: =0 -> 0
C36: JPX日経インデックス400先物 JPX-Nikkei Index 400 Futures | D36: 夜間 Night | E36: 470 | F36: =0 -> 0 | G36: 1707471500 | H36: =0 -> 0
D37: 前場 Morning | E37: 1191 | F37: =0 -> 0 | G37: 4274004000 | H37: =0 -> 0
D38: 後場 Afternoon | E38: 1845 | F38: =32 -> 32 | G38: 6528146980 | H38: =113577480 -> 113577480
D39: 合計 Total | E39: 3506 | F39: =32 -> 32 | G39: 12509622480 | H39: =113577480 -> 113577480
C40: TOPIX Core30先物 TOPIX Core30 Futures | D40: 夜間 Night | E40: 0 | F40: =0 -> 0 | G40: 0 | H40: =0 -> 0
D41: 前場 Morning | E41: 0 | F41: =0 -> 0 | G41: 0 | H41: =0 -> 0
...

Sheet market_data_OP
A1: JPXデリバティブ取引市況(オプション取引)
A2: JPX Derivatives Market Report
A3: =summary_data_Futures!A3:I3 -> 46220
A4: =summary_data_Futures!A4:I4 -> 46220
A6: （注）「総取引高」は立会取引及びJ-NETの合計、「うち立会外」はJ-NET分を内数表示。
A7: NOTE: Total : Total of Auction and J-NET Market
A8: J-NET : J-NET Market indicated in parentheses
B9: 商品名 | C9: 場区分 | D9: 取引高 （単位） Trading Volume (unit) | J9: 取引金額 （円） Trading Value (￥)
B10: Products | C10: Session | D10: プット put | F10: コール call | H10: 合計 Total | J10: プット put | L10: コール call | N10: 合計 Total
D11: 総取引高 Total | E11: うち立会外 J-NET | F11: 総取引高 Total | G11: うち立会外 J-NET | H11: 総取引高 Total | I11: うち立会外 J-NET | J11: 総取引代金 Total | K11: うち立会外 J-NET | L11: 総取引代金 Total | M11: うち立会外 J-NET | N11: 総取引代金 Total | O11: うち立会外 J-NET
A12: OSE | B12: 日経225オプション Nikkei 225 Options | C12: 夜間 Night | D12: =4842 -> 4842 | E12: =3641 -> 3641 | F12: =2385 -> 2385 | G12: =614 -> 614 | H12: =7227 -> 7227 | I12: =4255 -> 4255 | J12: =3318927380 -> 3318927380 | K12: =2885378380 -> 2885378380 | L12: =3384541620 -> 3384541620 | M12: =3019454620 -> 3019454620 | N12: =6703469000 -> 6703469000 | O12: =5904833000 -> 5904833000
C13: 前場 Morning | D13: =8010 -> 8010 | E13: =3646 -> 3646 | F13: =5559 -> 5559 | G13: =1913 -> 1913 | H13: =13569 -> 13569 | I13: =5559 -> 5559 | J13: =7394940970 -> 7394940970 | K13: =5051472970 -> 5051472970 | L13: =2859471620 -> 2859471620 | M13: =1473770620 -> 1473770620 | N13: =10254412590 -> 10254412590 | O13: =6525243590 -> 6525243590
C14: 後場 Afternoon | D14: =20431 -> 20431 | E14: =12076 -> 12076 | F14: =15789 -> 15789 | G14: =10064 -> 10064 | H14: =36220 -> 36220 | I14: =22140 -> 22140 | J14: =31844620060 -> 31844620060 | K14: =27171022060 -> 27171022060 | L14: =17314142500 -> 17314142500 | M14: =14232640500 -> 14232640500 | N14: =49158762560 -> 49158762560 | O14: =41403662560 -> 41403662560
C15: 合計 Total | D15: =33283 -> 33283 | E15: =19363 -> 19363 | F15: =23733 -> 23733 | G15: =12591 -> 12591 | H15: =57016 -> 57016 | I15: =31954 -> 31954 | J15: =42558488410 -> 42558488410 | K15: =35107873410 -> 35107873410 | L15: =23558155740 -> 23558155740 | M15: =18725865740 -> 18725865740 | N15: =66116644150 -> 66116644150 | O15: =53833739150 -> 53833739150
B16: 日経225ミニオプション Nikkei 225 mini Options | C16: 夜間 Night | D16: =5360 -> 5360 | E16: =180 -> 180 | F16: =7665 -> 7665 | G16: =390 -> 390 | H16: =13025 -> 13025 | I16: =570 -> 570 | J16: =533425020 -> 533425020 | K16: =9396920 -> 9396920 | L16: =367738770 -> 367738770 | M16: =9616270 -> 9616270 | N16: =901163790 -> 901163790 | O16: =19013190 -> 19013190
C17: 前場 Morning | D17: =5804 -> 5804 | E17: =230 -> 230 | F17: =12204 -> 12204 | G17: =1090 -> 1090 | H17: =18008 -> 18008 | I17: =1320 -> 1320 | J17: =640061080 -> 640061080 | K17: =26233780 -> 26233780 | L17: =372919830 -> 372919830 | M17: =31865430 -> 31865430 | N17: =1012980910 -> 1012980910 | O17: =58099210 -> 58099210
C18: 後場 Afternoon | D18: =4630 -> 4630 | E18: =10 -> 10 | F18: =19624 -> 19624 | G18: =660 -> 660 | H18: =24254 -> 24254 | I18: =670 -> 670 | J18: =715347510 -> 715347510 | K18: =6240010 -> 6240010 | L18: =766715450 -> 766715450 | M18: =14560950 -> 14560950 | N18: =1482062960 -> 1482062960 | O18: =20800960 -> 20800960
C19: 合計 Total | D19: =15794 -> 15794 | E19: =420 -> 420 | F19: =39493 -> 39493 | G19: =2140 -> 2140 | H19: =55287 -> 55287 | I19: =2560 -> 2560 | J19: =1888833610 -> 1888833610 | K19: =41870710 -> 41870710 | L19: =1507374050 -> 1507374050 | M19: =56042650 -> 56042650 | N19: =3396207660 -> 3396207660 | O19: =97913360 -> 97913360
B20: TOPIXオプション TOPIX Options | C20: 夜間 Night | D20: =80 -> 80 | E20: =80 -> 80 | F20: =80 -> 80 | G20: =80 -> 80 | H20: =160 -> 160 | I20: =160 -> 160 | J20: =184000000 -> 184000000 | K20: =184000000 -> 184000000 | L20: =152000000 -> 152000000 | M20: =152000000 -> 152000000 | N20: =336000000 -> 336000000 | O20: =336000000 -> 336000000
C21: 前場 Morning | D21: =1460 -> 1460 | E21: =1460 -> 1460 | F21: =80 -> 80 | G21: =80 -> 80 | H21: =1540 -> 1540 | I21: =1540 -> 1540 | J21: =3674401600 -> 3674401600 | K21: =3674401600 -> 3674401600 | L21: =152000000 -> 152000000 | M21: =152000000 -> 152000000 | N21: =3826401600 -> 3826401600 | O21: =3826401600 -> 3826401600
C22: 後場 Afternoon | D22: =823 -> 823 | E22: =808 -> 808 | F22: =0 -> 0 | G22: =0 -> 0 | H22: =823 -> 823 | I22: =808 -> 808 | J22: =970157628 -> 970157628 | K22: =963707628 -> 963707628 | L22: =0 -> 0 | M22: =0 -> 0 | N22: =970157628 -> 970157628 | O22: =963707628 -> 963707628
C23: 合計 Total | D23: =2363 -> 2363 | E23: =2348 -> 2348 | F23: =160 -> 160 | G23: =160 -> 160 | H23: =2523 -> 2523 | I23: =2508 -> 2508 | J23: =4828559228 -> 4828559228 | K23: =4822109228 -> 4822109228 | L23: =304000000 -> 304000000 | M23: =304000000 -> 304000000 | N23: =5132559228 -> 5132559228 | O23: =5126109228 -> 5126109228
B24: JPX日経インデックス400オプション JPX-Nikkei Index 400 Options | C24: 夜間 Night | D24: =0 -> 0 | E24: =0 -> 0 | F24: =0 -> 0 | G24: =0 -> 0 | H24: =0 -> 0 | I24: =0 -> 0 | J24: =0 -> 0 | K24: =0 -> 0 | ... O24: =0 -> 0
C25: 前場 Morning | D25: =0 -> 0 | E25: =0 -> 0 | F25: =0 -> 0 | G25: =0 -> 0 | H25: =0 -> 0 | I25: =0 -> 0 | J25: =0 -> 0 | K25: =0 -> 0 | ... O25: =0 -> 0
C26: 後場 Afternoon | D26: =0 -> 0 | E26: =0 -> 0 | F26: =0 -> 0 | G26: =0 -> 0 | H26: =0 -> 0 | I26: =0 -> 0 | J26: =0 -> 0 | K26: =0 -> 0 | ... O26: =0 -> 0
C27: 合計 Total | D27: =0 -> 0 | E27: =0 -> 0 | F27: =0 -> 0 | G27: =0 -> 0 | H27: =0 -> 0 | I27: =0 -> 0 | J27: =0 -> 0 | K27: =0 -> 0 | ... O27: =0 -> 0
B28: 東証銀行業株価指数オプション TOPIX Banks Index Options | C28: 夜間 Night | D28: =0 -> 0 | E28: =0 -> 0 | F28: =0 -> 0 | G28: =0 -> 0 | H28: =0 -> 0 | I28: =0 -> 0 | J28: =0 -> 0 | K28: =0 -> 0 | ... O28: =0 -> 0
C29: 前場 Morning | D29: =0 -> 0 | E29: =0 -> 0 | F29: =0 -> 0 | G29: =0 -> 0 | H29: =0 -> 0 | I29: =0 -> 0 | J29: =0 -> 0 | K29: =0 -> 0 | ... O29: =0 -> 0
C30: 後場 Afternoon | D30: =0 -> 0 | E30: =0 -> 0 | F30: =0 -> 0 | G30: =0 -> 0 | H30: =0 -> 0 | I30: =0 -> 0 | J30: =0 -> 0 | K30: =0 -> 0 | ... O30: =0 -> 0
C31: 合計 Total | D31: =0 -> 0 | E31: =0 -> 0 | F31: =0 -> 0 | G31: =0 -> 0 | H31: =0 -> 0 | I31: =0 -> 0 | J31: =0 -> 0 | K31: =0 -> 0 | ... O31: =0 -> 0
B32: 東証REIT指数オプション TSE REIT Index Options | C32: 夜間 Night | D32: =0 -> 0 | E32: =0 -> 0 | F32: =0 -> 0 | G32: =0 -> 0 | H32: =0 -> 0 | I32: =0 -> 0 | J32: =0 -> 0 | K32: =0 -> 0 | ... O32: =0 -> 0
C33: 前場 Morning | D33: =0 -> 0 | E33: =0 -> 0 | F33: =0 -> 0 | G33: =0 -> 0 | H33: =0 -> 0 | I33: =0 -> 0 | J33: =0 -> 0 | K33: =0 -> 0 | ... O33: =0 -> 0
C34: 後場 Afternoon | D34: =0 -> 0 | E34: =0 -> 0 | F34: =0 -> 0 | G34: =0 -> 0 | H34: =0 -> 0 | I34: =0 -> 0 | J34: =0 -> 0 | K34: =0 -> 0 | ... O34: =0 -> 0
C35: 合計 Total | D35: =0 -> 0 | E35: =0 -> 0 | F35: =0 -> 0 | G35: =0 -> 0 | H35: =0 -> 0 | I35: =0 -> 0 | J35: =0 -> 0 | K35: =0 -> 0 | ... O35: =0 -> 0
B36: 長期国債先物オプション取引 Options on 10-year JGB Futures | C36: 夜間 Night | D36: =0 -> 0 | E36: =0 -> 0 | F36: =0 -> 0 | G36: =0 -> 0 | H36: =0 -> 0 | I36: =0 -> 0 | J36: =0 -> 0 | K36: =0 -> 0 | ... O36: =0 -> 0
C37: 前場 Morning | D37: =0 -> 0 | E37: =0 -> 0 | F37: =51 -> 51 | G37: =0 -> 0 | H37: =51 -> 51 | I37: =0 -> 0 | J37: =0 -> 0 | K37: =0 -> 0 | L37: =9900000 -> 9900000 | M37: =0 -> 0 | N37: =9900000 -> 9900000 | O37: =0 -> 0
C38: 後場 Afternoon | D38: =85 -> 85 | E38: =15 -> 15 | F38: =356 -> 356 | G38: =45 -> 45 | H38: =441 -> 441 | I38: =60 -> 60 | J38: =9190000 -> 9190000 | K38: =1050000 -> 1050000 | L38: =31700000 -> 31700000 | M38: =5850000 -> 5850000 | N38: =40890000 -> 40890000 | O38: =6900000 -> 6900000
C39: 合計 Total | D39: =85 -> 85 | E39: =15 -> 15 | F39: =407 -> 407 | G39: =45 -> 45 | H39: =492 -> 492 | I39: =60 -> 60 | J39: =9190000 -> 9190000 | K39: =1050000 -> 1050000 | L39: =41600000 -> 41600000 | M39: =5850000 -> 5850000 | N39: =50790000 -> 50790000 | O39: =6900000 -> 6900000
B40: 有価証券オプション取引 Securities Options | C40: 夜間 Night | D40: ="－" -> － | E40: ="－" -> － | F40: ="－" -> － | G40: ="－" -> － | H40: ="－" -> － | I40: ="－" -> － | J40: ="－" -> － | K40: ="－" -> － | ... O40: ="－" -> －
C41: 前場 Morning | D41: =18601 -> 18601 | E41: =0 -> 0 | F41: =18099 -> 18099 | G41: =0 -> 0 | H41: =36700 -> 36700 | I41: =0 -> 0 | J41: =53600368 -> 53600368 | K41: =0 -> 0 | L41: =18203865 -> 18203865 | M41: =0 -> 0 | N41: =71804233 -> 71804233 | O41: =0 -> 0
...
